<mujoco model="openarm_grip">
  <compiler angle="radian" meshdir="./meshes"/>
  <option timestep="0.001" integrator="RK4" />

  <asset>
    <mesh name="base_link" file="base_link.stl" scale="0.001 0.001 0.001"/>
    <mesh name="J2_v1_1" file="J2_v1_1.stl" scale="0.001 0.001 0.001"/>
    <mesh name="J3_v1_1" file="J3_v1_1.stl" scale="0.001 0.001 0.001"/>
    <mesh name="J4_v1_1" file="J4_v1_1.stl" scale="0.001 0.001 0.001"/>
    <mesh name="J5_v1_1" file="J5_v1_1.stl" scale="0.001 0.001 0.001"/>
    <mesh name="J6_v1_1" file="J6_v1_1.stl" scale="0.001 0.001 0.001"/>
    <mesh name="J7_v1_1" file="J7_v1_1.stl" scale="0.001 0.001 0.001"/>
    <mesh name="grip_attach_1" file="grip_attach_1.stl" scale="0.001 0.001 0.001"/>
    <mesh name="left_jaw_1" file="left_jaw_1.stl" scale="0.001 0.001 0.001"/>
    <mesh name="right_jaw_1" file="right_jaw_1.stl" scale="0.001 0.001 0.001"/>
    <texture type="2d" name="grid" builtin="checker" mark="edge" rgb1="0.1 0.2 0.3" rgb2="0.2 0.3 0.4" markrgb="0.2 0.3 0.4" width="300" height="300"/>
    <material name="grid" texture="grid" texuniform="true" reflectance="0.2"/>
    <material name="self" rgba="0.7 0.5 0.3 1"/>
    <material name="self_default" rgba="0.7 0.5 0.3 1"/>
    <material name="self_highlight" rgba="0 0.5 0.3 1"/>
    <material name="effector" rgba="0.7 0.4 0.2 1"/>
    <material name="effector_default" rgba="0.7 0.4 0.2 1"/>
    <material name="effector_highlight" rgba="0 0.5 0.3 1"/>
    <material name="decoration" rgba="0.3 0.5 0.7 1"/>
    <material name="eye" rgba="0 0.2 1 1"/>
    <material name="target" rgba="0.6 0.3 0.3 1"/>
    <material name="target_default" rgba="0.6 0.3 0.3 1"/>
    <material name="target_highlight" rgba="0.6 0.3 0.3 0.4"/>
    <material name="site" rgba="0.5 0.5 0.5 0.3"/>
  </asset>

  <worldbody>
    <geom contype="0" conaffinity="0" type="mesh" rgba="0.7 0.7 0.7 1" mesh="base_link"/>
    <body name="J2_v1_1" pos="0 0 0">
      <inertial pos="0.00230073 -0.000216912 0.027606" quat="0.525523 0.473792 0.485545 0.513413" mass="0.49221" diaginertia="0.000717072 0.000591684 0.000314245"/>
      <joint name="rev1" pos="0 0 -0.00225" axis="0 0 1" range="-2.35619 2.35619" actuatorfrcrange="-100 100"/>
      <geom pos="0 0 0.00226" quat="1 0 0 0" type="mesh" rgba="0.7 0.7 0.7 1" mesh="J2_v1_1"/>
      <geom contype="0" conaffinity="0" pos="0 0 0.00225" quat="1 0 0 0" type="mesh" rgba="0.7 0.7 0.7 1" mesh="J2_v1_1"/>
      <body name="J3_v1_1" pos="0.02975 0 0.04475">
        <inertial pos="-0.0297259 0.0140847 0.00245888" quat="0.455807 0.546109 -0.5307 0.460827" mass="0.637283" diaginertia="0.000758429 0.000647067 0.000428504"/>
        <joint name="rev2" pos="0 0 0" axis="-1 0 0" range="-3.05433 0" actuatorfrcrange="-100 100"/>
        <geom contype="0" conaffinity="0" pos="-0.02975 0 -0.0425" quat="1 0 0 0" type="mesh" rgba="0.7 0.7 0.7 1" mesh="J3_v1_1"/>
        <geom pos="-0.02975 0 -0.0425" quat="1 0 0 0" type="mesh" rgba="0.7 0.7 0.7 1" mesh="J3_v1_1"/>
        <body name="J4_v1_1" pos="-0.02975 0.06041 0.010107">
          <inertial pos="8.40508e-05 0.135872 0.01843" quat="0.45455 0.528772 -0.543624 0.467181" mass="1.10255" diaginertia="0.0120429 0.0119049 0.000888171"/>
          <joint name="rev3" pos="0 0 0" axis="0 0.986291 0.165017" range="-2.0944 2.0944" actuatorfrcrange="-100 100"/>
          <geom contype="0" conaffinity="0" pos="0 -0.06041 -0.052607" quat="1 0 0 0" type="mesh" rgba="0.7 0.7 0.7 1" mesh="J4_v1_1"/>
          <geom pos="0 -0.06041 -0.052607" quat="1 0 0 0" type="mesh" rgba="0.7 0.7 0.7 1" mesh="J4_v1_1"/>
          <body name="J5_v1_1" pos="0.029755 0.238436 0.039893">
            <inertial pos="-0.0280868 -0.0623785 0.0151035" quat="0.555944 0.443417 -0.461389 0.530498" mass="0.729687" diaginertia="0.00291702 0.00247601 0.000779967"/>
            <joint name="rev4" pos="0 0 0" axis="1 0 0" range="-3.14159 0" actuatorfrcrange="-100 100"/>
            <geom contype="0" conaffinity="0" pos="-0.029755 -0.298846 -0.0925" quat="1 0 0 0" type="mesh" rgba="0.7 0.7 0.7 1" mesh="J5_v1_1"/>
            <geom pos="-0.029755 -0.298846 -0.0925" quat="1 0 0 0" type="mesh" rgba="0.7 0.7 0.7 1" mesh="J5_v1_1"/>
            <body name="J6_v1_1" pos="-0.029755 -0.13135 0.026265">
              <inertial pos="0.0164281 -0.0427155 0.00902392" quat="0.49268 0.561041 -0.302101 0.59265" mass="1.03391" diaginertia="0.00107864 0.000932243 0.000538114"/>
              <joint name="rev5" pos="0 0 0" axis="0 -0.980588 0.196078" range="-2.0944 2.0944" actuatorfrcrange="-100 100"/>
              <geom contype="0" conaffinity="0" pos="0 -0.167496 -0.118765" quat="1 0 0 0" type="mesh" rgba="0.7 0.7 0.7 1" mesh="J6_v1_1"/>
              <geom pos="0 -0.167496 -0.118765" quat="1 0 0 0" type="mesh" rgba="0.7 0.7 0.7 1" mesh="J6_v1_1"/>
              <body name="J7_v1_1" pos="0.0355 -0.1187 0.023735">
                <inertial pos="-0.0351069 0.000406626 0.00109366" quat="0.0784109 0.71275 0.0847134 0.691855" mass="0.33288" diaginertia="0.000208708 0.000177353 0.000139939"/>
                <joint name="rev6" pos="0 0 0" axis="-1 0 0" range="-1.5708 1.5708" actuatorfrcrange="-100 100"/>
                <geom contype="0" conaffinity="0" pos="-0.0355 -0.048796 -0.1425" quat="1 0 0 0" type="mesh" rgba="0.7 0.7 0.7 1" mesh="J7_v1_1"/>
                <geom pos="-0.0355 -0.048796 -0.1425" quat="1 0 0 0" type="mesh" rgba="0.7 0.7 0.7 1" mesh="J7_v1_1"/>
                <body name="grip_attach_1" pos="-0.0355 0.00303 0.01515">
                  <inertial pos="-3.54426e-05 -0.0809107 0.00406131" quat="0.494731 0.507414 -0.504134 0.49358" mass="0.818847" diaginertia="0.00155652 0.00111299 0.000609486"/>
                  <joint name="rev7" pos="0 0 0" axis="0 0.196078 0.980588" range="-0.5 0.5"/>
                  <geom contype="0" conaffinity="0" pos="0 -0.051826 -0.15765" quat="1 0 0 0" type="mesh" rgba="0.7 0.7 0.7 1" mesh="grip_attach_1"/>
                  <body name="left_jaw_1" pos="-0.0775 -0.121655 0.012086">
                    <inertial pos="0.017371 -0.0173984 0.00406215" quat="0.720768 0.686728 0.0942906 0.00280109" mass="0.286956" diaginertia="0.000211713 0.000184665 9.46214e-05"/>
                    <joint name="slider_left" pos="0 0 0" axis="-1 0 0" type="slide" range="-0.0455 0" />
                    <geom contype="0" conaffinity="0" pos="0.0775 0.069829 -0.169736" quat="1 0 0 0" type="mesh" rgba="0.7 0.7 0.7 1" mesh="left_jaw_1"/>
                    <geom pos="0.0775 0.069829 -0.169736" quat="1 0 0 0" type="mesh" rgba="0.7 0.7 0.7 1" mesh="left_jaw_1"/>
                  </body>
                  <body name="right_jaw_1" pos="0.0775 -0.121655 0.012086">
                    <inertial pos="-0.0173973 -0.0186854 -0.00174976" quat="0.846948 0.521671 -0.0167881 -0.101274" mass="0.285094" diaginertia="0.000213775 0.000188829 9.23967e-05"/>
                    <joint name="slider_right" pos="0 0 0" axis="1 0 0" type="slide" range="-0.0455 0"/>
                    <geom contype="0" conaffinity="0" pos="-0.0775 0.069829 -0.169736" quat="1 0 0 0" type="mesh" rgba="0.7 0.7 0.7 1" mesh="right_jaw_1"/>
                    <geom pos="-0.0775 0.069829 -0.169736" quat="1 0 0 0" type="mesh" rgba="0.7 0.7 0.7 1" mesh="right_jaw_1"/>
                  </body>
                </body>
              </body>
            </body>
          </body>
        </body>
      </body>
    </body>
    <camera name="side" pos="-0.082 -1.386 0.649" quat="0.812072 0.583554 0.0011671 0.00162414"/>
    <geom name="ground" size="0.5 0.5 0.1" type="plane" material="grid"/>
  </worldbody>

  <contact>
    <exclude name="gripper_contact" body1="left_jaw_1" body2="right_jaw_1"/>
  </contact>

  <tendon>
    <fixed name="split">
      <joint joint="slider_left" coef="0.5"/>
      <joint joint="slider_right" coef="0.5"/>
    </fixed>
  </tendon>
  <equality>
    <joint joint1="slider_left" joint2="slider_right" solimp="0.95 0.99 0.001" solref="0.005 1"/>
  </equality>

  <actuator>
    <position joint="rev1" name="rev1_actuator" kv="18.5" kp="85.0" ctrllimited="true" ctrlrange="-2.356194 2.356194"/>
    <position joint="rev2" name="rev2_actuator" kv="12.0" kp="50.0" ctrllimited="true" ctrlrange="-3.05433 0"/>
    <position joint="rev3" name="rev3_actuator" kv="8.0" kp="30.0" ctrllimited="true" ctrlrange="-2.0944 2.0944"/>
    <position joint="rev4" name="rev4_actuator" kv="10.0" kp="30.0" ctrllimited="true" ctrlrange="-3.14159 0"/>
    <position joint="rev5" name="rev5_actuator" kv="3.0" kp="27.5" ctrllimited="true" ctrlrange="-2.0944 2.0944"/>
    <position joint="rev6" name="rev6_actuator" kv="3.0" kp="35.0" ctrllimited="true" ctrlrange="-0.3 1.5708"/>
    <position joint="rev7" name="rev7_actuator" kv="3.0" kp="35.0" ctrllimited="true" ctrlrange="-0.5 0.5"/>
    <position name="gripper_actuator" tendon="split" kv="20.5" kp="100.0" ctrllimited="true" ctrlrange="-0.0455 0"/>

  </actuator>
</mujoco>
